try {
    throw 1;

} catch (e) {
    console.log(222)
    console.log('error', e);
}